Workbook

Sheet 分级母表
A1: GeneralName | B1: NewMatchWinRate | C1: 分级 | D1: 武将获取途径 | F1: 价格 | G1: 备注
A2: 武诸葛亮 | B2: 3000 | C2: T0 | D2: =VLOOKUP(A2,武将获取途径!$A:$D,4,0) -> 珍宝
A3: 武陆逊 | B3: 3000 | C3: T0 | D3: =VLOOKUP(A3,武将获取途径!$A:$D,4,0) -> 珍宝
A4: 乐蔡文姬 | B4: 3000 | C4: T0 | D4: =VLOOKUP(A4,武将获取途径!$A:$D,4,0) -> 纳贤
A5: 谋邓艾 | B5: 3000 | C5: T0 | D5: =VLOOKUP(A5,武将获取途径!$A:$D,4,0) -> 纳贤
A6: 威曹操 | B6: 3000 | C6: T0 | D6: =VLOOKUP(A6,武将获取途径!$A:$D,4,0) -> 珍宝
A7: 谋贾诩 | B7: 2992 | C7: T1 | D7: =VLOOKUP(A7,武将获取途径!$A:$D,4,0) -> 珍宝
A8: 威孙权 | B8: 2985 | C8: T1 | D8: =VLOOKUP(A8,武将获取途径!$A:$D,4,0) -> 祈福
A9: 王朗 | B9: 2979 | C9: T1 | D9: 国士商城
A10: 周宣 | B10: 2950 | C10: T1 | D10: =VLOOKUP(A10,武将获取途径!$A:$D,4,0) -> 纳贤
A11: 曹芳 | B11: 2949 | C11: T1 | D11: =VLOOKUP(A11,武将获取途径!$A:$D,4,0) -> 祈福
A12: 谋荀彧 | B12: 2947 | C12: T1 | D12: =VLOOKUP(A12,武将获取途径!$A:$D,4,0) -> 珍宝
A13: 神庞统 | B13: 2932 | C13: T1 | D13: =VLOOKUP(A13,武将获取途径!$A:$D,4,0) -> 珍宝
A14: 许靖 | B14: 2926 | C14: T1 | D14: =VLOOKUP(A14,武将获取途径!$A:$D,4,0) -> 祈福
A15: 神张飞 | B15: 2917 | C15: T1 | D15: =VLOOKUP(A15,武将获取途径!$A:$D,4,0) -> 宝玉兑换
A16: 神马超 | B16: 2912 | C16: T1 | D16: =VLOOKUP(A16,武将获取途径!$A:$D,4,0) -> 宝玉兑换
A17: 神黄忠 | B17: 2904 | C17: T1 | D17: =VLOOKUP(A17,武将获取途径!$A:$D,4,0) -> 珍宝
A18: 谋骆统 | B18: 2900 | C18: T1 | D18: =VLOOKUP(A18,武将获取途径!$A:$D,4,0) -> 充值奖励
A19: 滕芳兰 | B19: 2893 | C19: T1 | D19: =VLOOKUP(A19,武将获取途径!$A:$D,4,0) -> 祈福
A20: 神华佗 | B20: 2875 | C20: T1 | D20: =VLOOKUP(A20,武将获取途径!$A:$D,4,0) -> 珍宝
A21: 柏灵筠 | B21: 2871 | C21: T1 | D21: =VLOOKUP(A21,武将获取途径!$A:$D,4,0) -> 祈福
... A23: 星曹仁 | B23: 2843 | C23: T1 | D23: =VLOOKUP(A23,武将获取途径!$A:$D,4,0) -> 纳贤
A24: 武皇甫嵩 | B24: 2800 | C24: T1 | D24: 珍宝
A25: 神钟会 | B25: 2800 | C25: T1 | D25: =VLOOKUP(A25,武将获取途径!$A:$D,4,0) -> 珍宝
A26: 张奂 | B26: 2800 | C26: T1 | D26: =VLOOKUP(A26,武将获取途径!$A:$D,4,0) -> 宝玉兑换
A27: 威吕布 | B27: 2798 | C27: T2 | D27: =VLOOKUP(A27,武将获取途径!$A:$D,4,0) -> 珍宝
A28: 谋司马懿 | B28: 2786 | C28: T2 | D28: =VLOOKUP(A28,武将获取途径!$A:$D,4,0) -> 珍宝
A29: 威张辽 | B29: 2781 | C29: T2 | D29: =VLOOKUP(A29,武将获取途径!$A:$D,4,0) -> 珍宝
A30: 薛灵芸 | B30: 2781 | C30: T2 | D30: =VLOOKUP(A30,武将获取途径!$A:$D,4,0) -> 纳贤
A31: 武关羽 | B31: 2771 | C31: T2 | D31: =VLOOKUP(A31,武将获取途径!$A:$D,4,0) -> 珍宝
A32: 庞凤衣 | B32: 2762 | C32: T2 | D32: =VLOOKUP(A32,武将获取途径!$A:$D,4,0) -> 祈福
A33: 黄舞蝶 | B33: 2761 | C33: T2 | D33: =VLOOKUP(A33,武将获取途径!$A:$D,4,0) -> 纳贤
A34: 诸葛京 | B34: 2760 | C34: T2 | D34: =VLOOKUP(A34,武将获取途径!$A:$D,4,0) -> 祈福
A35: 庞宏 | B35: 2753 | C35: T2 | D35: =VLOOKUP(A35,武将获取途径!$A:$D,4,0) -> 纳贤
A36: 笮融 | B36: 2751 | C36: T2 | D36: =VLOOKUP(A36,武将获取途径!$A:$D,4,0) -> 纳贤
A37: 吴范 | B37: 2743 | C37: T2 | D37: 将符商店 | F37: 2000
A38: 丁尚涴 | B38: 2743 | C38: T2 | D38: =VLOOKUP(A38,武将获取途径!$A:$D,4,0) -> 砸蛋
A39: 刘衿刘佩 | B39: 2735 | C39: T2 | D39: =VLOOKUP(A39,武将获取途径!$A:$D,4,0) -> 祈福
A40: 谋张绣 | B40: 2731 | C40: T2 | D40: =VLOOKUP(A40,武将获取途径!$A:$D,4,0) -> 纳贤
A41: 关宁 | B41: 2727 | C41: T2 | D41: =VLOOKUP(A41,武将获取途径!$A:$D,4,0) -> 充值奖励
...

Sheet 武将获取途径
A1: 武将名称（备注用 | B1: 武将唯一ID | C1: 获取途径id | D1: 获取途径
A2: 神吕蒙 | B2: 202 | C2: 5002 | D2: =VLOOKUP(C2,Sheet5!$A$1:$B$22,2,0) -> 神将任务
A3: 神周瑜 | B3: 203 | C3: 5002 | D3: =VLOOKUP(C3,Sheet5!$A$1:$B$22,2,0) -> 神将任务
A4: 神诸葛亮 | B4: 204 | C4: 5002 | D4: =VLOOKUP(C4,Sheet5!$A$1:$B$22,2,0) -> 神将任务
A5: 神曹操 | B5: 205 | C5: 5002 | D5: =VLOOKUP(C5,Sheet5!$A$1:$B$22,2,0) -> 神将任务
A6: 神吕布 | B6: 206 | C6: 5002 | D6: =VLOOKUP(C6,Sheet5!$A$1:$B$22,2,0) -> 神将任务
A7: 神赵云 | B7: 207 | C7: 5002 | D7: =VLOOKUP(C7,Sheet5!$A$1:$B$22,2,0) -> 神将任务
A8: 神司马懿 | B8: 208 | C8: 5002 | D8: =VLOOKUP(C8,Sheet5!$A$1:$B$22,2,0) -> 神将任务
A9: 神刘备 | B9: 209 | C9: 5002 | D9: =VLOOKUP(C9,Sheet5!$A$1:$B$22,2,0) -> 神将任务
A10: 神陆逊 | B10: 210 | C10: 5002 | D10: =VLOOKUP(C10,Sheet5!$A$1:$B$22,2,0) -> 神将任务
A11: 神张辽 | B11: 211 | C11: 5002 | D11: =VLOOKUP(C11,Sheet5!$A$1:$B$22,2,0) -> 神将任务
A12: 神甘宁 | B12: 212 | C12: 5002 | D12: =VLOOKUP(C12,Sheet5!$A$1:$B$22,2,0) -> 神将任务
A13: 神马超 | B13: 214 | C13: 1101 | D13: =VLOOKUP(C13,Sheet5!$A$1:$B$22,2,0) -> 宝玉兑换
... A309: 谋吴懿 | B309: 2317 | C309: 1001 | D309: =VLOOKUP(C309,Sheet5!$A$1:$B$22,2,0) -> 纳贤

Sheet Sheet1
A1: 武将道具唯一ID | B1: 武将名称 | C1: 道具类型 | D1: 武将ID | E1: 武将分级
A2: 400010 | B2: 刘备 | C2: 武将 | D2: 1
A3: 400020 | B3: 关羽 | C3: 武将 | D3: 2
A4: 400030 | B4: 张飞 | C4: 武将 | D4: 3
A5: 400040 | B5: 诸葛亮 | C5: 武将 | D5: 4
A6: 400050 | B6: 赵云 | C6: 武将 | D6: 5
A7: 400060 | B7: 马超 | C7: 武将 | D7: 6
A8: 400070 | B8: 黄月英 | C8: 武将 | D8: 7
A9: 400080 | B9: 孙权 | C9: 武将 | D9: 8
A10: 400090 | B10: 甘宁 | C10: 武将 | D10: 9
A11: 400100 | B11: 吕蒙 | C11: 武将 | D11: 10
A12: 400110 | B12: 黄盖 | C12: 武将 | D12: 11
A13: 400120 | B13: 周瑜 | C13: 武将 | D13: 12
... A664: 4024110 | B664: 星张松 | C664: 武将 | D664: 2411

Sheet Sheet5
A1: 获取途径id | B1: 获取途径
A2: 2 | B2: 将星招募
A3: 1001 | B3: 纳贤
A4: 1004 | B4: 祈福
A5: 1002 | B5: 如意签
A6: 1003 | B6: 珍宝
A7: 1101 | B7: 宝玉兑换
A8: 2000 | B8: 首充
A9: 2001 | B9: 砸蛋
A10: 2002 | B10: 充值奖励
A11: 2003 | B11: 累充奖励
A12: 2004 | B12: 连连看
A13: 3002 | B13: 活跃
... A19: 5007 | B19: 商城礼包
A20: #N/A | B20: 招募
A21: 23 | B21: 武将收集
A22: 103 | B22: 官阶

Sheet Sheet6

Sheet 当前环境有一战之力的武将
A1: 武将名 | B1: 将面分 | C1: 分级 | D1: 武将获取途径 | E1: 价格
A2: 吴范 | B2: 2743 | C2: T2 | D2: 将符商店 | E2: 2000 | G2: =VLOOKUP(A2,武将获取途径!$A:$D,2,0) -> #N/A
A3: 张琪瑛 | B3: 2700 | C3: T2 | D3: 将符商店 | E3: 10000 | G3: =VLOOKUP(A3,武将获取途径!$A:$D,2,0) -> #N/A
A4: 留赞 | B4: 2591 | C4: T3 | D4: 将符商店 | E4: 6000 | G4: =VLOOKUP(A4,武将获取途径!$A:$D,2,0) -> #N/A
A5: 陈珪 | B5: 2560 | C5: T3 | D5: 将符商店 | E5: 2000 | G5: =VLOOKUP(A5,武将获取途径!$A:$D,2,0) -> 1033
A6: 徐荣 | B6: 2544 | C6: T3 | D6: 将符商店 | E6: 10000 | G6: =VLOOKUP(A6,武将获取途径!$A:$D,2,0) -> #N/A
A7: 孙綝 | B7: 2502 | C7: T3 | D7: 将符商店 | E7: 2000 | G7: =VLOOKUP(A7,武将获取途径!$A:$D,2,0) -> #N/A
A8: 苏越 | B8: 2500 | C8: T3 | D8: 喵喵杀 | E8: 无 | G8: =VLOOKUP(A8,武将获取途径!$A:$D,2,0) -> 1911
A9: 张嫙 | B9: 2498 | C9: T3 | D9: 将符商店 | E9: 5000 | G9: =VLOOKUP(A9,武将获取途径!$A:$D,2,0) -> 1017
A10: 黄承彦 | B10: 2496 | C10: T3 | D10: 将符商店 | E10: 3000 | G10: =VLOOKUP(A10,武将获取途径!$A:$D,2,0) -> #N/A
A11: 蒲元 | B11: 2494 | C11: T3 | D11: 将符商店 | E11: 2000 | G11: =VLOOKUP(A11,武将获取途径!$A:$D,2,0) -> #N/A
A12: 胡班 | B12: 2476 | C12: T3 | D12: 将符商店 | E12: 1500 | G12: =VLOOKUP(A12,武将获取途径!$A:$D,2,0) -> 1122
A13: 杜夔 | B13: 2466 | C13: T3 | D13: 将符商店 | E13: 2000 | G13: =VLOOKUP(A13,武将获取途径!$A:$D,2,0) -> 805
A14: 王昶 | B14: 2378 | C14: T4 | D14: 将符商店 | E14: 2000 | G14: =VLOOKUP(A14,武将获取途径!$A:$D,2,0) -> #N/A
A15: 牛辅 | B15: 2363 | C15: T4 | D15: 将符商店 | E15: 1000 | G15: =VLOOKUP(A15,武将获取途径!$A:$D,2,0) -> 610
A16: 滕公主 | B16: 2353 | C16: T4 | D16: 将符商店 | E16: 3000 | G16: =VLOOKUP(A16,武将获取途径!$A:$D,2,0) -> 1007
A17: 刘永 | B17: 2345 | C17: T4 | D17: 将符商店 | E17: 1000 | G17: =VLOOKUP(A17,武将获取途径!$A:$D,2,0) -> #N/A
A18: 赵襄 | B18: 2342 | C18: T4 | D18: 将符商店 | E18: 10000 | G18: =VLOOKUP(A18,武将获取途径!$A:$D,2,0) -> #N/A
A19: 南华老仙 | B19: 2337 | C19: T4 | D19: 将符商店 | E19: 6000 | G19: =VLOOKUP(A19,武将获取途径!$A:$D,2,0) -> 551
A20: 界凌统 | B20: 2331 | C20: T4 | D20: 将星招募 | E20: 破界石*3 | F20: 免费 | G20: =VLOOKUP(A20,武将获取途径!$A:$D,2,0) -> #N/A
A21: 樊玉凤 | B21: 2329 | C21: T4 | D21: 将符商店 | E21: 3000 | G21: =VLOOKUP(A21,武将获取途径!$A:$D,2,0) -> #N/A
A22: 王烈 | B22: 2321 | C22: T4 | D22: 将符商店 | E22: 2000 | G22: =VLOOKUP(A22,武将获取途径!$A:$D,2,0) -> 1953
A23: 曹婴 | B23: 2286 | C23: T4 | D23: 将符商店 | E23: 10000 | G23: =VLOOKUP(A23,武将获取途径!$A:$D,2,0) -> #N/A
A24: 陆凯 | B24: 2286 | C24: T4 | D24: 将符商店 | E24: 2000 | G24: =VLOOKUP(A24,武将获取途径!$A:$D,2,0) -> 1150
A25: 郭照 | B25: 2280 | C25: T4 | D25: 将符商店 | E25: 5000 | G25: =VLOOKUP(A25,武将获取途径!$A:$D,2,0) -> #N/A
A26: 吕玲绮 | B26: 2276 | C26: T4 | D26: 将符商店 | E26: 6000 | G26: =VLOOKUP(A26,武将获取途径!$A:$D,2,0) -> 549
A27: 胡金定 | B27: 2274 | C27: T4 | D27: 将符商店 | E27: 2000 | G27: =VLOOKUP(A27,武将获取途径!$A:$D,2,0) -> 1123
A28: 冯方 | B28: 2273 | C28: T4 | D28: 将符商店 | E28: 1500 | G28: =VLOOKUP(A28,武将获取途径!$A:$D,2,0) -> #N/A
A29: 胡昭 | B29: 2242 | C29: T4 | D29: 将符商店 | E29: 1000 | G29: =VLOOKUP(A29,武将获取途径!$A:$D,2,0) -> 1952
A30: 谋黄盖 | B30: 2194 | C30: T5 | D30: 活跃活动 | E30: 免费 | G30: =VLOOKUP(A30,武将获取途径!$A:$D,2,0) -> 1682
A31: 张媱 | B31: 2193 | C31: T5 | D31: 将符商店 | E31: 2000 | G31: =VLOOKUP(A31,武将获取途径!$A:$D,2,0) -> #N/A
A32: 庞德公 | B32: 2190 | C32: T5 | D32: 将符商店 | E32: 3000 | G32: =VLOOKUP(A32,武将获取途径!$A:$D,2,0) -> #N/A
A33: 严夫人 | B33: 2187 | C33: T5 | D33: 将符商店 | E33: 1000 | G33: =VLOOKUP(A33,武将获取途径!$A:$D,2,0) -> #N/A
A34: 潘淑 | B34: 2178 | C34: T5 | D34: 将符商店 | E34: 3000 | G34: =VLOOKUP(A34,武将获取途径!$A:$D,2,0) -> 546
A35: 界张松 | B35: 2176 | C35: T5 | D35: 将星招募 | E35: 破界石*3 | G35: =VLOOKUP(A35,武将获取途径!$A:$D,2,0) -> #N/A
A36: 赵昂 | B36: 2175 | C36: T5 | D36: 将符商店 | E36: 2000 | G36: =VLOOKUP(A36,武将获取途径!$A:$D,2,0) -> #N/A
A37: 赵嫣 | B37: 2170 | C37: T5 | D37: 将符商店 | E37: 1500 | G37: =VLOOKUP(A37,武将获取途径!$A:$D,2,0) -> #N/A
A38: 诸葛尚 | B38: 2159 | C38: T5 | D38: 将符商店 | E38: 2000 | G38: =VLOOKUP(A38,武将获取途径!$A:$D,2,0) -> 1153
A39: 界曹叡 | B39: 2144 | C39: T5 | D39: 将星招募 | E39: 破界石*3 | G39: =VLOOKUP(A39,武将获取途径!$A:$D,2,0) -> #N/A
A40: 杨仪 | B40: 2141 | C40: T5 | D40: 将符商店 | E40: 1000 | G40: =VLOOKUP(A40,武将获取途径!$A:$D,2,0) -> #N/A
...

Sheet 可用的低付费武将
A1: 武将名 | B1: 将面分 | C1: 分级 | D1: 武将获取途径 | E1: 价格 | G1: 武将名 | H1: 将面分 | I1: 分级 | J1: 武将获取途径 | K1: 价格 | M1: 武将名 | N1: 将面分 | O1: 分级 | P1: 武将获取途径 | Q1: 价格
A2: 谋黄盖 | B2: 2194 | C2: T5 | D2: 活跃活动 | E2: 免费 | G2: 牛辅 | H2: 2363 | I2: T4 | J2: 将符商店 | K2: 1000 | M2: 吴范 | N2: 2743 | O2: T2 | P2: 将符商店 | Q2: 2000
A3: 界吴懿 | B3: 2064 | C3: T5 | D3: 将符商店 | E3: 20 | G3: 刘永 | H3: 2345 | I3: T4 | J3: 将符商店 | K3: 1000 | M3: 陈珪 | N3: 2560 | O3: T3 | P3: 将符商店 | Q3: 2000
A4: 陆绩 | B4: 2035 | C4: T5 | D4: 将符商店 | E4: 60 | G4: 胡昭 | H4: 2242 | I4: T4 | J4: 将符商店 | K4: 1000 | M4: 孙綝 | N4: 2502 | O4: T3 | P4: 将符商店 | Q4: 2000
A5: 界钟会 | B5: 2047 | C5: T5 | D5: 将符商店 | E5: 60符+破界石*3 | G5: 严夫人 | H5: 2187 | I5: T5 | J5: 将符商店 | K5: 1000 | M5: 蒲元 | N5: 2494 | O5: T3 | P5: 将符商店 | Q5: 2000
A6: 界钟繇 | B6: 2030 | C6: T5 | D6: 将符商店 | E6: 60符+破界石*3 | G6: 杨仪 | H6: 2141 | I6: T5 | J6: 将符商店 | K6: 1000 | M6: 杜夔 | N6: 2466 | O6: T3 | P6: 将符商店 | Q6: 2000
A7: 李傕 | B7: 2059 | C7: T5 | D7: 将符商店 | E7: 140 | G7: 羊祜 | H7: 2125 | I7: T5 | J7: 将符商店 | K7: 1000 | M7: 王昶 | N7: 2378 | O7: T4 | P7: 将符商店 | Q7: 2000
A8: 尹夫人 | B8: 2140 | C8: T5 | D8: 将符商店 | E8: 500 | G8: SP贾诩 | H8: 2091 | I8: T5 | J8: 将符商店 | K8: 1000 | M8: 王烈 | N8: 2321 | O8: T4 | P8: 将符商店 | Q8: 2000
A9: 邓芝 | B9: 2077 | C9: T5 | D9: 将符商店 | E9: 500 | G9: 卞喜 | H9: 2071 | I9: T5 | J9: 将符商店 | K9: 1000 | M9: 陆凯 | N9: 2286 | O9: T4 | P9: 将符商店 | Q9: 2000
A10: 陈式 | D10: 活跃活动 | G10: 公孙度 | H10: 2065 | I10: T5 | J10: 将符商店 | K10: 1000 | M10: 胡金定 | N10: 2274 | O10: T4 | P10: 将符商店 | Q10: 2000
A11: 苏飞 | D11: 活跃活动 | G11: sp孟获 | H11: 2064 | I11: T5 | J11: 将符商店 | K11: 1000 | M11: 张媱 | N11: 2193 | O11: T5 | P11: 将符商店 | Q11: 2000
G12: 葛玄 | H12: 2031 | I12: T5 | J12: 将符商店 | K12: 1000 | M12: 赵昂 | N12: 2175 | O12: T5 | P12: 将符商店 | Q12: 2000
G13: 黄权 | H13: 2056 | I13: T5 | J13: 将符商店 | K13: 1000 | M13: 诸葛尚 | N13: 2159 | O13: T5 | P13: 将符商店 | Q13: 2000
A14: 可以一战： | G14: 田畴 | H14: 2000 | I14: T5 | J14: 将符商店 | K14: 1000 | M14: 刘巴 | N14: 2131 | O14: T5 | P14: 将符商店 | Q14: 2000
A15: 界朱治 | B15: 1987 | C15: T6 | D15: 招募 | E15: 1 | G15: 胡班 | H15: 2476 | I15: T3 | J15: 将符商店 | K15: 1500 | M15: 杨婉 | N15: 2115 | O15: T5 | P15: 将符商店 | Q15: 2000
A16: 界陈宫 | B16: 1978 | C16: T6 | D16: 招募 | E16: 1 | G16: 冯方 | H16: 2273 | I16: T4 | J16: 将符商店 | K16: 1500 | M16: 管亥 | N16: 2113 | O16: T5 | P16: 将符商店 | Q16: 2000
A17: 许攸 | B17: 1965 | C17: T6 | D17: 招募 | E17: 1 | G17: 赵嫣 | H17: 2170 | I17: T5 | J17: 将符商店 | K17: 1500 | M17: 黄承彦 | N17: 2496 | O17: T3 | P17: 将符商店 | Q17: 3000
A18: 曹昂 | B18: 1956 | C18: T6 | D18: 招募 | E18: 1 | G18: 曹安民 | H18: 2122 | I18: T5 | J18: 将符商店 | K18: 1500 | M18: 滕公主 | N18: 2353 | O18: T4 | P18: 将符商店 | Q18: 3000
A19: 戏志才 | B19: 1940 | C19: T6 | D19: 招募 | E19: 1 | G19: 何晏 | H19: 2030 | I19: T5 | J19: 将符商店 | K19: 1500 | M19: 樊玉凤 | N19: 2329 | O19: T4 | P19: 将符商店 | Q19: 3000
A20: 郝昭 | B20: 1914 | C20: T6 | D20: 招募 | E20: 1 | M20: 庞德公 | N20: 2190 | O20: T5 | P20: 将符商店 | Q20: 3000
A21: 曹叡 | B21: 1901 | C21: T6 | D21: 招募 | E21: 1 | M21: 潘淑 | N21: 2178 | O21: T5 | P21: 将符商店 | Q21: 3000
A22: 张绣 | B22: 1796 | C22: T7 | D22: 招募 | E22: 1 | M22: 阮瑀 | N22: 2102 | O22: T5 | P22: 将符商店 | Q22: 3000
A23: 界关平 | B23: 1790 | C23: T7 | D23: 招募 | E23: 1 | M23: 张嫙 | N23: 2498 | O23: T3 | P23: 将符商店 | Q23: 5000
A24: 界张飞 | B24: 1726 | C24: T7 | D24: 招募 | E24: 1 | M24: 郭照 | N24: 2280 | O24: T4 | P24: 将符商店 | Q24: 5000
A25: 界黄盖 | B25: 1725 | C25: T7 | D25: 招募 | E25: 1 | M25: 留赞 | N25: 2591 | O25: T3 | P25: 将符商店 | Q25: 6000
A26: 刘禅 | B26: 1559 | C26: T8 | D26: 招募 | E26: 1 | M26: 南华老仙 | N26: 2337 | O26: T4 | P26: 将符商店 | Q26: 6000
A27: 刘焉 | B27: 1519 | C27: T8 | D27: 新人特惠 | E27: 1 | M27: 吕玲绮 | N27: 2276 | O27: T4 | P27: 将符商店 | Q27: 6000
A28: 鲁肃 | B28: 1492 | C28: T8 | D28: 招募 | E28: 1 | M28: 张琪瑛 | N28: 2700 | O28: T2 | P28: 将符商店 | Q28: 10000
A29: 魏延 | B29: 1390 | C29: T9 | D29: 招募 | E29: 1 | M29: 徐荣 | N29: 2544 | O29: T3 | P29: 将符商店 | Q29: 10000
A30: 关平 | B30: 1372 | C30: T9 | D30: 招募 | E30: 1 | M30: 赵襄 | N30: 2342 | O30: T4 | P30: 将符商店 | Q30: 10000
M31: 曹婴 | N31: 2286 | O31: T4 | P31: 将符商店 | Q31: 10000
M32: 曹纯 | N32: 2139 | O32: T5 | P32: 将符商店 | Q32: 10000
A34: 夏侯杰 | B34: 2133 | C34: T5 | D34: 活跃 | E34: 无双武将 | F34: 免费
A35: 神甘宁 | B35: 2140 | C35: T5 | D35: 神将任务 | E35: 随机碰运气 | F35: 免费
A36: 界张松 | B36: 2176 | C36: T5 | D36: 将星招募 | E36: 破界石*3
A37: 界曹叡 | B37: 2144 | C37: T5 | D37: 将星招募 | E37: 破界石*3
A38: 界SP黄月英 | B38: 2115 | C38: T5 | D38: 将星招募 | E38: 36个巅峰宝珠
A39: 马腾 | B39: 2095 | C39: T5 | D39: 将星招募 | E39: 随机碰运气
A40: 界法正 | B40: 2090 | C40: T5 | D40: 将星招募 | E40: 破界石*3
A41: 界文聘 | B41: 2090 | C41: T5 | D41: 将星招募 | E41: 36个巅峰宝珠
...

Sheet Sheet8
A1: 谋黄盖 | B1: 2194 | C1: T5 | D1: 活跃活动 | E1: 免费 | K1: 武将名 | L1: 将面分 | M1: 分级 | N1: 武将获取途径 | O1: 价格
A2: 界吴懿 | B2: 2064 | C2: T5 | D2: 将符商店 | E2: 20 | F2: 牛辅 | G2: 2363 | H2: T4 | I2: 将符商店 | J2: 1000 | K2: 吴范 | L2: 2743 | M2: T2 | N2: 将符商店 | O2: 2000
A3: 陆绩 | B3: 2035 | C3: T5 | D3: 将符商店 | E3: 60 | F3: 刘永 | G3: 2345 | H3: T4 | I3: 将符商店 | J3: 1000 | K3: 陈珪 | L3: 2560 | M3: T3 | N3: 将符商店 | O3: 2000 | Z3: 张琪瑛 | AA3: 2700 | AB3: T2 | AC3: 将符商店 | AD3: 10000
A4: 界钟会 | B4: 2047 | C4: T5 | D4: 将符商店 | E4: 60符+破界石*3 | F4: 胡昭 | G4: 2242 | H4: T4 | I4: 将符商店 | J4: 1000 | K4: 孙綝 | L4: 2502 | M4: T3 | N4: 将符商店 | O4: 2000 | P4: 张嫙 | Q4: 2498 | R4: T3 | S4: 将符商店 | T4: 5000 | U4: 留赞 | V4: 2591 | W4: T3 | X4: 将符商店 | Y4: 6000 | Z4: 徐荣 | AA4: 2544 | AB4: T3 | AC4: 将符商店 | AD4: 10000
A5: 界钟繇 | B5: 2030 | C5: T5 | D5: 将符商店 | E5: 60符+破界石*3 | F5: 严夫人 | G5: 2187 | H5: T5 | I5: 将符商店 | J5: 1000 | K5: 蒲元 | L5: 2494 | M5: T3 | N5: 将符商店 | O5: 2000 | P5: 郭照 | Q5: 2280 | R5: T4 | S5: 将符商店 | T5: 5000 | U5: 南华老仙 | V5: 2337 | W5: T4 | X5: 将符商店 | Y5: 6000 | Z5: 赵襄 | AA5: 2342 | AB5: T4 | AC5: 将符商店 | AD5: 10000
A6: 李傕 | B6: 2059 | C6: T5 | D6: 将符商店 | E6: 140 | F6: 杨仪 | G6: 2141 | H6: T5 | I6: 将符商店 | J6: 1000 | K6: 杜夔 | L6: 2466 | M6: T3 | N6: 将符商店 | O6: 2000 | U6: 吕玲绮 | V6: 2276 | W6: T4 | X6: 将符商店 | Y6: 6000 | Z6: 曹婴 | AA6: 2286 | AB6: T4 | AC6: 将符商店 | AD6: 10000
F7: 羊祜 | G7: 2125 | H7: T5 | I7: 将符商店 | J7: 1000 | K7: 王昶 | L7: 2378 | M7: T4 | N7: 将符商店 | O7: 2000 | Z7: 曹纯 | AA7: 2139 | AB7: T5 | AC7: 将符商店 | AD7: 10000
K8: 苏越 | L8: 2500 | M8: T3 | N8: 喵喵杀 | O8: 无
F9: SP贾诩 | G9: 2091 | H9: T5 | I9: 将符商店 | J9: 1000 | K9: 王烈 | L9: 2321 | M9: T4 | N9: 将符商店 | O9: 2000
F10: 卞喜 | G10: 2071 | H10: T5 | I10: 将符商店 | J10: 1000 | K10: 陆凯 | L10: 2286 | M10: T4 | N10: 将符商店 | O10: 2000
A11: 尹夫人 | B11: 2140 | C11: T5 | D11: 将符商店 | E11: 500 | F11: 公孙度 | G11: 2065 | H11: T5 | I11: 将符商店 | J11: 1000 | K11: 胡金定 | L11: 2274 | M11: T4 | N11: 将符商店 | O11: 2000
A12: 邓芝 | B12: 2077 | C12: T5 | D12: 将符商店 | E12: 500 | F12: sp孟获 | G12: 2064 | H12: T5 | I12: 将符商店 | J12: 1000 | K12: 张媱 | L12: 2193 | M12: T5 | N12: 将符商店 | O12: 2000
F13: 葛玄 | G13: 2031 | H13: T5 | I13: 将符商店 | J13: 1000 | K13: 赵昂 | L13: 2175 | M13: T5 | N13: 将符商店 | O13: 2000
F14: 黄权 | G14: 2056 | H14: T5 | I14: 将符商店 | J14: 1000 | K14: 诸葛尚 | L14: 2159 | M14: T5 | N14: 将符商店 | O14: 2000
K15: 刘巴 | L15: 2131 | M15: T5 | N15: 将符商店 | O15: 2000
K16: 杨婉 | L16: 2115 | M16: T5 | N16: 将符商店 | O16: 2000
K17: 管亥 | L17: 2113 | M17: T5 | N17: 将符商店 | O17: 2000
K18: 田畴 | L18: 2000 | M18: T5 | N18: 将符商店 | O18: 1000
K20: 界凌统 | L20: 2331 | M20: T4 | N20: 将星招募 | O20: 破界石*3
F23: 胡班 | G23: 2476 | H23: T3 | I23: 将符商店 | J23: 1500 | K23: 黄承彦 | L23: 2496 | M23: T3 | N23: 将符商店 | O23: 3000
F24: 冯方 | G24: 2273 | H24: T4 | I24: 将符商店 | J24: 1500 | K24: 滕公主 | L24: 2353 | M24: T4 | N24: 将符商店 | O24: 3000
F25: 赵嫣 | G25: 2170 | H25: T5 | I25: 将符商店 | J25: 1500 | K25: 樊玉凤 | L25: 2329 | M25: T4 | N25: 将符商店 | O25: 3000
F26: 曹安民 | G26: 2122 | H26: T5 | I26: 将符商店 | J26: 1500 | K26: 庞德公 | L26: 2190 | M26: T5 | N26: 将符商店 | O26: 3000
F27: 何晏 | G27: 2030 | H27: T5 | I27: 将符商店 | J27: 1500 | K27: 潘淑 | L27: 2178 | M27: T5 | N27: 将符商店 | O27: 3000
K28: 阮瑀 | L28: 2102 | M28: T5 | N28: 将符商店 | O28: 3000
K35: 界张松 | L35: 2176 | M35: T5 | N35: 将星招募 | O35: 破界石*3
K39: 界曹叡 | L39: 2144 | M39: T5 | N39: 将星招募 | O39: 破界石*3
K42: 神甘宁 | L42: 2140 | M42: T5 | N42: 神将任务 | O42: 随机碰运气
K44: 夏侯杰 | L44: 2133 | M44: T5 | N44: 活跃 | O44: 无双武将
K48: 界SP黄月英 | L48: 2115 | M48: T5 | N48: 将星招募 | O48: 36个巅峰宝珠
K52: 马腾 | L52: 2095 | M52: T5 | N52: 将星招募 | O52: 随机碰运气
K54: 界法正 | L54: 2090 | M54: T5 | N54: 将星招募 | O54: 破界石*3
K55: 界文聘 | L55: 2090 | M55: T5 | N55: 将星招募 | O55: 36个巅峰宝珠
K56: 界马忠 | L56: 2080 | M56: T5 | N56: 将星招募 | O56: 48个巅峰宝珠
K62: 界陈群 | L62: 2061 | M62: T5 | N62: 将星招募 | O62: 破界石*3
K65: 界王异 | L65: 2053 | M65: T5 | N65: 活跃活动 | O65: 破界石*3
K66: 神陆逊 | L66: 2049 | M66: T5 | N66: 神将任务 | O66: 随机碰运气
... K74: 神典韦 | L74: 2000 | M74: T5 | N74: 周年庆 | O74: 无
